<mujoco model="phonebot">
	<!-- everything at 10x scale -->
	<compiler angle="radian" coordinate="local" inertiafromgeom="true"/>
	<option integrator="Euler" timestep="0.0001" gravity="0 0 -98.1" iterations='10000'/>

	<visual>
		<map znear="0.01"/>
	</visual>

	<default>
		<joint armature="0.1" damping="1.0" limited="true"/>
		<geom conaffinity="0" condim="3" density="5.0" friction="1 0.5 0.5" margin="0.01" rgba="0.8 0.6 0.4 1"/>
	</default>

	<asset>
		<texture builtin="gradient" height="100" rgb1="1 1 1" rgb2="0 0 0" type="skybox" width="100"/>
		<texture builtin="flat" height="1278" mark="cross" markrgb="1 1 1" name="texgeom" random="0.01" rgb1="0.8 0.6 0.4" rgb2="0.8 0.6 0.4" type="cube" width="127"/>
		<texture builtin="checker" height="100" name="texplane" rgb1="0 0 0" rgb2="0.8 0.8 0.8" type="2d" width="100"/>
		<material name="MatPlane" reflectance="0.5" shininess="1" specular="1" texrepeat="60 60" texture="texplane"/>
		<material name="geom" texture="texgeom" texuniform="true"/>
	</asset>

	<worldbody>
		<light cutoff="100" diffuse="1 1 1" dir="-0 0 -1.3" directional="true" exponent="1" pos="0 0 1.3" specular=".1 .1 .1"/>
		<geom conaffinity="1" condim="3" material="MatPlane" name="floor" pos="0 0 0" rgba="0.8 0.9 0.8 1" size="40 40 40" type="plane"/>
		<body name="torso" pos="0 0 1.0">

			<inertial pos="0 0 0" mass="138."/>
			<geom name="torso_geom" pos="0 0 -0.0706" size="0.75 0.38175 0.10806" type="box"/>

			<geom name="fl_stop" pos="0.41418 0.425 -0.10148" size="0.04" type="sphere"/>
			<geom name="fr_stop" pos="0.41418 -0.425 -0.10148" size="0.04" type="sphere"/>
			<geom name="bl_stop" pos="-0.41418 0.425 -0.10148" size="0.04" type="sphere"/>
			<geom name="br_stop" pos="-0.41418 -0.425 -0.10148" size="0.04" type="sphere"/>

			<!--
			<inertial pos="0 0 0" mass="0.138" diaginertia="7.23e-5 0.000264 7.23e-5"/>
			-->

			<!-- UNCOMMENT TO ENABLE GRAVITY -->
			<!-- <joint armature="0" damping="0" limited="false" margin="0.01" name="root" pos="0 0 0" type="free"/> -->
			<body name="fl_leg" pos="0.41418 0.425 -0.10148">
				<body pos="-0.110 0 0">
					<joint axis="0 1 0" name="fl_ma" pos="0.0 0.0 0.0" range="-1.5707 0" type="hinge"/>
					<geom fromto="0.0 0.0 0.0 -0.175 0.0 0.0" name="fl_1a_geom" size="0.04" type="capsule"/>
					<body pos="-0.175 0.0 0">
						<joint axis="0 1 0" name="fl_ja" pos="0.0 0.0 0.0" limited="false" type="hinge"/>
						<geom fromto="0.0 0.0 0.0 0.285 0.0 0.0" name="fl_2a_geom" size="0.04" type="capsule"/>
						<body pos="0.285 0.0 0.0" name="fl_ep_a">
							<geom name="fl_ep_a_geom" size="0.02" type="sphere"/>
						</body>
					</body>
				</body>
				<body pos="0.110 0 0">
					<joint axis="0 -1 0" name="fl_mb" pos="0.0 0.0 0.0" range="-1.5707 0" type="hinge"/>
					<geom fromto="0.0 0.0 0.0 0.175 0.0 0.0" name="fl_1b_geom" size="0.04" type="capsule"/>
					<body pos="0.175 0.0 0">
						<joint axis="0 -1 0" name="fl_jb" pos="0.0 0.0 0.0" limited="false" type="hinge"/>
						<geom fromto="0.0 0.0 0.0 -0.285 0.0 0.0" name="fl_2b_geom" size="0.04" type="capsule"/>
						<body pos="-0.285 0.0 0.0" name="fl_ep_b">
							<geom name="fl_ep_b_geom" size="0.02" type="sphere"/>
						</body>
					</body>
				</body>
			</body>

			<body name="fr_leg" pos="0.41418 -0.425 -0.10148">
				<body pos="-0.110 0 0">
					<joint axis="0 1 0" name="fr_ma" pos="0.0 0.0 0.0" range="-1.5707 0" type="hinge"/>
					<geom fromto="0.0 0.0 0.0 -0.175 0.0 0.0" name="fr_1a_geom" size="0.04" type="capsule"/>
					<body pos="-0.175 0.0 0">
						<joint axis="0 1 0" name="fr_ja" pos="0.0 0.0 0.0" limited="false" type="hinge"/>
						<geom fromto="0.0 0.0 0.0 0.285 0.0 0.0" name="fr_2a_geom" size="0.04" type="capsule"/>
						<body pos="0.285 0.0 0.0" name="fr_ep_a">
							<geom name="fr_ep_a_geom" size="0.02" type="sphere"/>
						</body>
					</body>
				</body>
				<body pos="0.110 0 0">
					<joint axis="0 -1 0" name="fr_mb" pos="0.0 0.0 0.0" range="-1.5707 0" type="hinge"/>
					<geom fromto="0.0 0.0 0.0 0.175 0.0 0.0" name="fr_1b_geom" size="0.04" type="capsule"/>
					<body pos="0.175 0.0 0">
						<joint axis="0 -1 0" name="fr_jb" pos="0.0 0.0 0.0" limited="false" type="hinge"/>
						<geom fromto="0.0 0.0 0.0 -0.285 0.0 0.0" name="fr_2b_geom" size="0.04" type="capsule"/>
						<body pos="-0.285 0.0 0.0" name="fr_ep_b">
							<geom name="fr_ep_b_geom" size="0.02" type="sphere"/>
						</body>
					</body>
				</body>
			</body>

			<body name="bl_leg" pos="-0.41418 0.425 -0.10148">
				<body pos="-0.110 0 0">
					<joint axis="0 1 0" name="bl_ma" pos="0.0 0.0 0.0" range="-1.5707 0" type="hinge"/>
					<geom fromto="0.0 0.0 0.0 -0.175 0.0 0.0" name="bl_1a_geom" size="0.04" type="capsule"/>
					<body pos="-0.175 0.0 0">
						<joint axis="0 1 0" name="bl_ja" pos="0.0 0.0 0.0" limited="false" type="hinge"/>
						<geom fromto="0.0 0.0 0.0 0.285 0.0 0.0" name="bl_2a_geom" size="0.04" type="capsule"/>
						<body pos="0.285 0.0 0.0" name="bl_ep_a">
							<geom name="bl_ep_a_geom" size="0.02" type="sphere"/>
						</body>
					</body>
				</body>
				<body pos="0.110 0 0">
					<joint axis="0 -1 0" name="bl_mb" pos="0.0 0.0 0.0" range="-1.5707 0" type="hinge"/>
					<geom fromto="0.0 0.0 0.0 0.175 0.0 0.0" name="bl_1b_geom" size="0.04" type="capsule"/>
					<body pos="0.175 0.0 0">
						<joint axis="0 -1 0" name="bl_jb" pos="0.0 0.0 0.0" limited="false" type="hinge"/>
						<geom fromto="0.0 0.0 0.0 -0.285 0.0 0.0" name="bl_2b_geom" size="0.04" type="capsule"/>
						<body pos="-0.285 0.0 0.0" name="bl_ep_b">
							<geom name="bl_ep_b_geom" size="0.02" type="sphere"/>
						</body>
					</body>
				</body>
			</body>

			<body name="br_leg" pos="-0.41418 -0.425 -0.10148">
				<body pos="-0.110 0 0">
					<joint axis="0 1 0" name="br_ma" pos="0.0 0.0 0.0" range="-1.5707 0" type="hinge"/>
					<geom fromto="0.0 0.0 0.0 -0.175 0.0 0.0" name="br_1a_geom" size="0.04" type="capsule"/>
					<body pos="-0.175 0.0 0">
						<joint axis="0 1 0" name="br_ja" pos="0.0 0.0 0.0" limited="false" type="hinge"/>
						<geom fromto="0.0 0.0 0.0 0.285 0.0 0.0" name="br_2a_geom" size="0.04" type="capsule"/>
						<body pos="0.285 0.0 0.0" name="br_ep_a">
							<geom name="br_ep_a_geom" size="0.02" type="sphere"/>
						</body>
					</body>
				</body>
				<body pos="0.110 0 0">
					<joint axis="0 -1 0" name="br_mb" pos="0.0 0.0 0.0" range="-1.5707 0" type="hinge"/>
					<geom fromto="0.0 0.0 0.0 0.175 0.0 0.0" name="br_1b_geom" size="0.04" type="capsule"/>
					<body pos="0.175 0.0 0">
						<joint axis="0 -1 0" name="br_jb" pos="0.0 0.0 0.0" limited="false" type="hinge"/>
						<geom fromto="0.0 0.0 0.0 -0.285 0.0 0.0" name="br_2b_geom" size="0.04" type="capsule"/>
						<body pos="-0.285 0.0 0.0" name="br_ep_b">
							<geom name="br_ep_b_geom" size="0.02" type="sphere"/>
						</body>
					</body>
				</body>
			</body>
		</body>
	</worldbody>
    <equality>
		<connect name="fl_ep" body1="fl_ep_a" body2="fl_ep_b" anchor="0 0 0" active="true"/>
		<connect name="fr_ep" body1="fr_ep_a" body2="fr_ep_b" anchor="0 0 0" active="true"/>
		<connect name="bl_ep" body1="bl_ep_a" body2="bl_ep_b" anchor="0 0 0" active="true"/>
		<connect name="br_ep" body1="br_ep_a" body2="br_ep_b" anchor="0 0 0" active="true"/>
    </equality>
	<contact>
		<pair geom1="fl_stop" geom2="fl_ep_a_geom" margin="0.1"/>
		<pair geom1="fl_stop" geom2="fl_ep_b_geom" margin="0.1"/>
		<pair geom1="fr_stop" geom2="fr_ep_a_geom" margin="0.1"/>
		<pair geom1="fr_stop" geom2="fr_ep_b_geom" margin="0.1"/>
		<pair geom1="bl_stop" geom2="bl_ep_a_geom" margin="0.1"/>
		<pair geom1="bl_stop" geom2="bl_ep_b_geom" margin="0.1"/>
		<pair geom1="br_stop" geom2="br_ep_a_geom" margin="0.1"/>
		<pair geom1="br_stop" geom2="br_ep_b_geom" margin="0.1"/>
	</contact>
	<actuator>
		<motor ctrllimited="true" ctrlrange="-1.0 1.0" joint="fl_ma" gear="500"/>
		<motor ctrllimited="true" ctrlrange="-1.0 1.0" joint="fl_mb" gear="500"/>
		<motor ctrllimited="true" ctrlrange="-1.0 1.0" joint="fr_ma" gear="500"/>
		<motor ctrllimited="true" ctrlrange="-1.0 1.0" joint="fr_mb" gear="500"/>
		<motor ctrllimited="true" ctrlrange="-1.0 1.0" joint="bl_ma" gear="500"/>
		<motor ctrllimited="true" ctrlrange="-1.0 1.0" joint="bl_mb" gear="500"/>
		<motor ctrllimited="true" ctrlrange="-1.0 1.0" joint="br_ma" gear="500"/>
		<motor ctrllimited="true" ctrlrange="-1.0 1.0" joint="br_mb" gear="500"/>

		<!--
		<position ctrllimited="false" ctrlrange="-1.57 0" joint="fl_ma"/>
		<position ctrllimited="false" ctrlrange="-1.57 0" joint="fl_mb"/>
		<position ctrllimited="false" ctrlrange="-1.57 0" joint="fr_ma"/>
		<position ctrllimited="false" ctrlrange="-1.57 0" joint="fr_mb"/>
		<position ctrllimited="false" ctrlrange="-1.57 0" joint="bl_ma"/>
		<position ctrllimited="false" ctrlrange="-1.57 0" joint="bl_mb"/>
		<position ctrllimited="false" ctrlrange="-1.57 0" joint="br_ma"/>
		<position ctrllimited="false" ctrlrange="-1.57 0" joint="br_mb"/>
		-->
	</actuator>
</mujoco>
