<?xml version="0.0" ?>
<robot name="phonebot">
    <link name="body">
        <inertial>
            <origin rpy="0.00000000000000000000000000000000 -0.00000000000000000000000000000000 0.00000000000000000000000000000000" xyz="0.00000000000000000000000000000000 0.00000000000000000000000000000000 0.00000000000000000000000000000000"/>
            <mass value="0.13800000000000001154631945610163"/>
            <inertia ixx="0.00007240861200600001148716677868" ixy="0" ixz="0" iyy="0.00026412140325600001787911819129" iyz="0" izz="0.00032578720875000004991717261760"/>
        </inertial>
        <visual>
            <origin rpy="0.00000000000000000000000000000000 -0.00000000000000000000000000000000 0.00000000000000000000000000000000" xyz="0.00000000000000000000000000000000 0.00000000000000000000000000000000 0.00000000000000000000000000000000"/>
            <geometry>
                <box size="0.14999999999999999444888487687422 0.07635000000000000119904086659517 0.02161199999999999926680871453755"/>
            </geometry>
            <material name="mat_-1_0">
                <color rgba="0.00000000000000000000000000000000 1.00000000000000000000000000000000 1.00000000000000000000000000000000 0.50000000000000000000000000000000" />
            </material>
        </visual>
        <collision>
            <origin rpy="0.00000000000000000000000000000000 -0.00000000000000000000000000000000 0.00000000000000000000000000000000" xyz="0.00000000000000000000000000000000 0.00000000000000000000000000000000 0.00000000000000000000000000000000"/>
            <geometry>
                <box size="0.14999999999999999444888487687422 0.07635000000000000119904086659517 0.02161199999999999926680871453755"/>
            </geometry>
        </collision>
    </link>
    <link name="FL_leg_origin">
        <inertial>
            <origin rpy="0.00000000000000000000000000000000 -0.00000000000000000000000000000000 0.00000000000000000000000000000000" xyz="0.00000000000000000000000000000000 0.00000000000000000000000000000000 0.00000000000000000000000000000000"/>
            <mass value="0.00200000000000000004163336342344"/>
            <inertia ixx="0.00000001280000000000000212069335" ixy="0" ixz="0" iyy="0.00000001280000000000000212069335" iyz="0" izz="0.00000001280000000000000212069335"/>
        </inertial>
        <visual>
            <origin rpy="0.00000000000000000000000000000000 -0.00000000000000000000000000000000 0.00000000000000000000000000000000" xyz="0.00000000000000000000000000000000 0.00000000000000000000000000000000 0.00000000000000000000000000000000"/>
            <geometry>
                <sphere radius="0.00400000000000000008326672684689"/>
            </geometry>
            <material name="mat_0_0">
                <color rgba="1.00000000000000000000000000000000 1.00000000000000000000000000000000 1.00000000000000000000000000000000 1.00000000000000000000000000000000" />
            </material>
        </visual>
        <collision>
            <origin rpy="0.00000000000000000000000000000000 -0.00000000000000000000000000000000 0.00000000000000000000000000000000" xyz="0.00000000000000000000000000000000 0.00000000000000000000000000000000 0.00000000000000000000000000000000"/>
            <geometry>
                <sphere radius="0.00400000000000000008326672684689"/>
            </geometry>
        </collision>
    </link>
    <link name="FL_hip_joint_a_link_fake"></link>
    <link name="FL_hip_link_a">
        <inertial>
            <origin rpy="0.00000000000000000000000000000000 -0.00000000000000000000000000000000 0.00000000000000000000000000000000" xyz="0.00000000000000000000000000000000 0.00000000000000000000000000000000 0.00000000000000000000000000000000"/>
            <mass value="0.02999999999999999888977697537484"/>
            <inertia ixx="0.00000031999999999999942436006823" ixy="0" ixz="0" iyy="0.00000092562499999999981980912259" iyz="0" izz="0.00000092562499999999981980912259"/>
        </inertial>
        <visual>
            <origin rpy="0.00000000000000000000000000000000 1.57079632679489655799898173427209 -0.00000000000000000000000000000000" xyz="0.00000000000000000000000000000000 0.00000000000000000000000000000000 0.00000000000000000000000000000000"/>
            <geometry>
                <cylinder length="0.01750000000000000166533453693773" radius="0.00400000000000000008326672684689"/>
            </geometry>
            <material name="mat_2_0">
                <color rgba="1.00000000000000000000000000000000 1.00000000000000000000000000000000 1.00000000000000000000000000000000 1.00000000000000000000000000000000" />
            </material>
        </visual>
        <collision>
            <origin rpy="0.00000000000000000000000000000000 1.57079632679489655799898173427209 -0.00000000000000000000000000000000" xyz="0.00000000000000000000000000000000 0.00000000000000000000000000000000 0.00000000000000000000000000000000"/>
            <geometry>
                <cylinder length="0.01750000000000000166533453693773" radius="0.00399999999999999661381977489327"/>
            </geometry>
        </collision>
    </link>
    <link name="FL_knee_joint_a_link_fake"></link>
    <link name="FL_knee_link_a">
        <inertial>
            <origin rpy="0.00000000000000000000000000000000 -0.00000000000000000000000000000000 0.00000000000000000000000000000000" xyz="0.00000000000000000000000000000000 0.00000000000000000000000000000000 0.00000000000000000000000000000000"/>
            <mass value="0.02999999999999999888977697537484"/>
            <inertia ixx="0.00000031999999999999942436006823" ixy="0" ixz="0" iyy="0.00000219062499999999946080999659" iyz="0" izz="0.00000219062499999999946080999659"/>
        </inertial>
        <visual>
            <origin rpy="0.00000000000000000000000000000000 1.57079632679489655799898173427209 -0.00000000000000000000000000000000" xyz="0.00000000000000000000000000000000 0.00000000000000000000000000000000 0.00000000000000000000000000000000"/>
            <geometry>
                <cylinder length="0.02850000000000000102695629777827" radius="0.00400000000000000008326672684689"/>
            </geometry>
            <material name="mat_4_0">
                <color rgba="1.00000000000000000000000000000000 1.00000000000000000000000000000000 1.00000000000000000000000000000000 1.00000000000000000000000000000000" />
            </material>
        </visual>
        <collision>
            <origin rpy="0.00000000000000000000000000000000 1.57079632679489655799898173427209 -0.00000000000000000000000000000000" xyz="0.00000000000000000000000000000000 0.00000000000000000000000000000000 0.00000000000000000000000000000000"/>
            <geometry>
                <cylinder length="0.02849999999999999755750934582466" radius="0.00399999999999999661381977489327"/>
            </geometry>
        </collision>
    </link>
    <link name="FL_foot_link_a">
        <inertial>
            <origin rpy="0.00000000000000000000000000000000 -0.00000000000000000000000000000000 0.00000000000000000000000000000000" xyz="0.00000000000000000000000000000000 0.00000000000000000000000000000000 0.00000000000000000000000000000000"/>
            <mass value="0.01000000000000000020816681711722"/>
            <inertia ixx="0.00000006400000000000000398602185" ixy="0" ixz="0" iyy="0.00000006400000000000000398602185" iyz="0" izz="0.00000006400000000000000398602185"/>
        </inertial>
        <visual>
            <origin rpy="0.00000000000000000000000000000000 -0.00000000000000000000000000000000 0.00000000000000000000000000000000" xyz="0.00000000000000000000000000000000 0.00000000000000000000000000000000 0.00000000000000000000000000000000"/>
            <geometry>
                <sphere radius="0.00400000000000000008326672684689"/>
            </geometry>
            <material name="mat_5_0">
                <color rgba="1.00000000000000000000000000000000 1.00000000000000000000000000000000 1.00000000000000000000000000000000 1.00000000000000000000000000000000" />
            </material>
        </visual>
        <collision>
            <origin rpy="0.00000000000000000000000000000000 -0.00000000000000000000000000000000 0.00000000000000000000000000000000" xyz="0.00000000000000000000000000000000 0.00000000000000000000000000000000 0.00000000000000000000000000000000"/>
            <geometry>
                <sphere radius="0.00400000000000000008326672684689"/>
            </geometry>
        </collision>
    </link>
    <link name="FL_hip_joint_b_link_fake"></link>
    <link name="FL_hip_link_b">
        <inertial>
            <origin rpy="0.00000000000000000000000000000000 -0.00000000000000000000000000000000 0.00000000000000000000000000000000" xyz="0.00000000000000000000000000000000 0.00000000000000000000000000000000 0.00000000000000000000000000000000"/>
            <mass value="0.02999999999999999888977697537484"/>
            <inertia ixx="0.00000031999999999999942436006823" ixy="0" ixz="0" iyy="0.00000092562499999999981980912259" iyz="0" izz="0.00000092562499999999981980912259"/>
        </inertial>
        <visual>
            <origin rpy="0.00000000000000000000000000000000 1.57079632679489655799898173427209 -0.00000000000000000000000000000000" xyz="0.00000000000000000000000000000000 0.00000000000000000000000000000000 0.00000000000000000000000000000000"/>
            <geometry>
                <cylinder length="0.01750000000000000166533453693773" radius="0.00400000000000000008326672684689"/>
            </geometry>
            <material name="mat_7_0">
                <color rgba="1.00000000000000000000000000000000 1.00000000000000000000000000000000 1.00000000000000000000000000000000 1.00000000000000000000000000000000" />
            </material>
        </visual>
        <collision>
            <origin rpy="0.00000000000000000000000000000000 1.57079632679489655799898173427209 -0.00000000000000000000000000000000" xyz="0.00000000000000000000000000000000 0.00000000000000000000000000000000 0.00000000000000000000000000000000"/>
            <geometry>
                <cylinder length="0.01750000000000000166533453693773" radius="0.00399999999999999661381977489327"/>
            </geometry>
        </collision>
    </link>
    <link name="FL_knee_joint_b_link_fake"></link>
    <link name="FL_knee_link_b">
        <inertial>
            <origin rpy="0.00000000000000000000000000000000 -0.00000000000000000000000000000000 0.00000000000000000000000000000000" xyz="0.00000000000000000000000000000000 0.00000000000000000000000000000000 0.00000000000000000000000000000000"/>
            <mass value="0.02999999999999999888977697537484"/>
            <inertia ixx="0.00000031999999999999942436006823" ixy="0" ixz="0" iyy="0.00000219062499999999946080999659" iyz="0" izz="0.00000219062499999999946080999659"/>
        </inertial>
        <visual>
            <origin rpy="0.00000000000000000000000000000000 1.57079632679489655799898173427209 -0.00000000000000000000000000000000" xyz="0.00000000000000000000000000000000 0.00000000000000000000000000000000 0.00000000000000000000000000000000"/>
            <geometry>
                <cylinder length="0.02850000000000000102695629777827" radius="0.00400000000000000008326672684689"/>
            </geometry>
            <material name="mat_9_0">
                <color rgba="1.00000000000000000000000000000000 1.00000000000000000000000000000000 1.00000000000000000000000000000000 1.00000000000000000000000000000000" />
            </material>
        </visual>
        <collision>
            <origin rpy="0.00000000000000000000000000000000 1.57079632679489655799898173427209 -0.00000000000000000000000000000000" xyz="0.00000000000000000000000000000000 0.00000000000000000000000000000000 0.00000000000000000000000000000000"/>
            <geometry>
                <cylinder length="0.02849999999999999755750934582466" radius="0.00399999999999999661381977489327"/>
            </geometry>
        </collision>
    </link>
    <link name="FL_foot_link_b">
        <inertial>
            <origin rpy="0.00000000000000000000000000000000 -0.00000000000000000000000000000000 0.00000000000000000000000000000000" xyz="0.00000000000000000000000000000000 0.00000000000000000000000000000000 0.00000000000000000000000000000000"/>
            <mass value="0.01000000000000000020816681711722"/>
            <inertia ixx="0.00000006400000000000000398602185" ixy="0" ixz="0" iyy="0.00000006400000000000000398602185" iyz="0" izz="0.00000006400000000000000398602185"/>
        </inertial>
        <visual>
            <origin rpy="0.00000000000000000000000000000000 -0.00000000000000000000000000000000 0.00000000000000000000000000000000" xyz="0.00000000000000000000000000000000 0.00000000000000000000000000000000 0.00000000000000000000000000000000"/>
            <geometry>
                <sphere radius="0.00400000000000000008326672684689"/>
            </geometry>
            <material name="mat_10_0">
                <color rgba="1.00000000000000000000000000000000 1.00000000000000000000000000000000 1.00000000000000000000000000000000 1.00000000000000000000000000000000" />
            </material>
        </visual>
        <collision>
            <origin rpy="0.00000000000000000000000000000000 -0.00000000000000000000000000000000 0.00000000000000000000000000000000" xyz="0.00000000000000000000000000000000 0.00000000000000000000000000000000 0.00000000000000000000000000000000"/>
            <geometry>
                <sphere radius="0.00400000000000000008326672684689"/>
            </geometry>
        </collision>
    </link>
    <link name="FR_leg_origin">
        <inertial>
            <origin rpy="0.00000000000000000000000000000000 -0.00000000000000000000000000000000 0.00000000000000000000000000000000" xyz="0.00000000000000000000000000000000 0.00000000000000000000000000000000 0.00000000000000000000000000000000"/>
            <mass value="0.00200000000000000004163336342344"/>
            <inertia ixx="0.00000001280000000000000212069335" ixy="0" ixz="0" iyy="0.00000001280000000000000212069335" iyz="0" izz="0.00000001280000000000000212069335"/>
        </inertial>
        <visual>
            <origin rpy="0.00000000000000000000000000000000 -0.00000000000000000000000000000000 0.00000000000000000000000000000000" xyz="0.00000000000000000000000000000000 0.00000000000000000000000000000000 0.00000000000000000000000000000000"/>
            <geometry>
                <sphere radius="0.00400000000000000008326672684689"/>
            </geometry>
            <material name="mat_11_0">
                <color rgba="1.00000000000000000000000000000000 1.00000000000000000000000000000000 1.00000000000000000000000000000000 1.00000000000000000000000000000000" />
            </material>
        </visual>
        <collision>
            <origin rpy="0.00000000000000000000000000000000 -0.00000000000000000000000000000000 0.00000000000000000000000000000000" xyz="0.00000000000000000000000000000000 0.00000000000000000000000000000000 0.00000000000000000000000000000000"/>
            <geometry>
                <sphere radius="0.00400000000000000008326672684689"/>
            </geometry>
        </collision>
    </link>
    <link name="FR_hip_joint_a_link_fake"></link>
    <link name="FR_hip_link_a">
        <inertial>
            <origin rpy="0.00000000000000000000000000000000 -0.00000000000000000000000000000000 0.00000000000000000000000000000000" xyz="0.00000000000000000000000000000000 0.00000000000000000000000000000000 0.00000000000000000000000000000000"/>
            <mass value="0.02999999999999999888977697537484"/>
            <inertia ixx="0.00000031999999999999942436006823" ixy="0" ixz="0" iyy="0.00000092562499999999981980912259" iyz="0" izz="0.00000092562499999999981980912259"/>
        </inertial>
        <visual>
            <origin rpy="0.00000000000000000000000000000000 1.57079632679489655799898173427209 -0.00000000000000000000000000000000" xyz="0.00000000000000000000000000000000 0.00000000000000000000000000000000 0.00000000000000000000000000000000"/>
            <geometry>
                <cylinder length="0.01750000000000000166533453693773" radius="0.00400000000000000008326672684689"/>
            </geometry>
            <material name="mat_13_0">
                <color rgba="1.00000000000000000000000000000000 1.00000000000000000000000000000000 1.00000000000000000000000000000000 1.00000000000000000000000000000000" />
            </material>
        </visual>
        <collision>
            <origin rpy="0.00000000000000000000000000000000 1.57079632679489655799898173427209 -0.00000000000000000000000000000000" xyz="0.00000000000000000000000000000000 0.00000000000000000000000000000000 0.00000000000000000000000000000000"/>
            <geometry>
                <cylinder length="0.01750000000000000166533453693773" radius="0.00399999999999999661381977489327"/>
            </geometry>
        </collision>
    </link>
    <link name="FR_knee_joint_a_link_fake"></link>
    <link name="FR_knee_link_a">
        <inertial>
            <origin rpy="0.00000000000000000000000000000000 -0.00000000000000000000000000000000 0.00000000000000000000000000000000" xyz="0.00000000000000000000000000000000 0.00000000000000000000000000000000 0.00000000000000000000000000000000"/>
            <mass value="0.02999999999999999888977697537484"/>
            <inertia ixx="0.00000031999999999999942436006823" ixy="0" ixz="0" iyy="0.00000219062499999999946080999659" iyz="0" izz="0.00000219062499999999946080999659"/>
        </inertial>
        <visual>
            <origin rpy="0.00000000000000000000000000000000 1.57079632679489655799898173427209 -0.00000000000000000000000000000000" xyz="0.00000000000000000000000000000000 0.00000000000000000000000000000000 0.00000000000000000000000000000000"/>
            <geometry>
                <cylinder length="0.02850000000000000102695629777827" radius="0.00400000000000000008326672684689"/>
            </geometry>
            <material name="mat_15_0">
                <color rgba="1.00000000000000000000000000000000 1.00000000000000000000000000000000 1.00000000000000000000000000000000 1.00000000000000000000000000000000" />
            </material>
        </visual>
        <collision>
            <origin rpy="0.00000000000000000000000000000000 1.57079632679489655799898173427209 -0.00000000000000000000000000000000" xyz="0.00000000000000000000000000000000 0.00000000000000000000000000000000 0.00000000000000000000000000000000"/>
            <geometry>
                <cylinder length="0.02849999999999999755750934582466" radius="0.00399999999999999661381977489327"/>
            </geometry>
        </collision>
    </link>
    <link name="FR_foot_link_a">
        <inertial>
            <origin rpy="0.00000000000000000000000000000000 -0.00000000000000000000000000000000 0.00000000000000000000000000000000" xyz="0.00000000000000000000000000000000 0.00000000000000000000000000000000 0.00000000000000000000000000000000"/>
            <mass value="0.01000000000000000020816681711722"/>
            <inertia ixx="0.00000006400000000000000398602185" ixy="0" ixz="0" iyy="0.00000006400000000000000398602185" iyz="0" izz="0.00000006400000000000000398602185"/>
        </inertial>
        <visual>
            <origin rpy="0.00000000000000000000000000000000 -0.00000000000000000000000000000000 0.00000000000000000000000000000000" xyz="0.00000000000000000000000000000000 0.00000000000000000000000000000000 0.00000000000000000000000000000000"/>
            <geometry>
                <sphere radius="0.00400000000000000008326672684689"/>
            </geometry>
            <material name="mat_16_0">
                <color rgba="1.00000000000000000000000000000000 1.00000000000000000000000000000000 1.00000000000000000000000000000000 1.00000000000000000000000000000000" />
            </material>
        </visual>
        <collision>
            <origin rpy="0.00000000000000000000000000000000 -0.00000000000000000000000000000000 0.00000000000000000000000000000000" xyz="0.00000000000000000000000000000000 0.00000000000000000000000000000000 0.00000000000000000000000000000000"/>
            <geometry>
                <sphere radius="0.00400000000000000008326672684689"/>
            </geometry>
        </collision>
    </link>
    <link name="FR_hip_joint_b_link_fake"></link>
    <link name="FR_hip_link_b">
        <inertial>
            <origin rpy="0.00000000000000000000000000000000 -0.00000000000000000000000000000000 0.00000000000000000000000000000000" xyz="0.00000000000000000000000000000000 0.00000000000000000000000000000000 0.00000000000000000000000000000000"/>
            <mass value="0.02999999999999999888977697537484"/>
            <inertia ixx="0.00000031999999999999942436006823" ixy="0" ixz="0" iyy="0.00000092562499999999981980912259" iyz="0" izz="0.00000092562499999999981980912259"/>
        </inertial>
        <visual>
            <origin rpy="0.00000000000000000000000000000000 1.57079632679489655799898173427209 -0.00000000000000000000000000000000" xyz="0.00000000000000000000000000000000 0.00000000000000000000000000000000 0.00000000000000000000000000000000"/>
            <geometry>
                <cylinder length="0.01750000000000000166533453693773" radius="0.00400000000000000008326672684689"/>
            </geometry>
            <material name="mat_18_0">
                <color rgba="1.00000000000000000000000000000000 1.00000000000000000000000000000000 1.00000000000000000000000000000000 1.00000000000000000000000000000000" />
            </material>
        </visual>
        <collision>
            <origin rpy="0.00000000000000000000000000000000 1.57079632679489655799898173427209 -0.00000000000000000000000000000000" xyz="0.00000000000000000000000000000000 0.00000000000000000000000000000000 0.00000000000000000000000000000000"/>
            <geometry>
                <cylinder length="0.01750000000000000166533453693773" radius="0.00399999999999999661381977489327"/>
            </geometry>
        </collision>
    </link>
    <link name="FR_knee_joint_b_link_fake"></link>
    <link name="FR_knee_link_b">
        <inertial>
            <origin rpy="0.00000000000000000000000000000000 -0.00000000000000000000000000000000 0.00000000000000000000000000000000" xyz="0.00000000000000000000000000000000 0.00000000000000000000000000000000 0.00000000000000000000000000000000"/>
            <mass value="0.02999999999999999888977697537484"/>
            <inertia ixx="0.00000031999999999999942436006823" ixy="0" ixz="0" iyy="0.00000219062499999999946080999659" iyz="0" izz="0.00000219062499999999946080999659"/>
        </inertial>
        <visual>
            <origin rpy="0.00000000000000000000000000000000 1.57079632679489655799898173427209 -0.00000000000000000000000000000000" xyz="0.00000000000000000000000000000000 0.00000000000000000000000000000000 0.00000000000000000000000000000000"/>
            <geometry>
                <cylinder length="0.02850000000000000102695629777827" radius="0.00400000000000000008326672684689"/>
            </geometry>
            <material name="mat_20_0">
                <color rgba="1.00000000000000000000000000000000 1.00000000000000000000000000000000 1.00000000000000000000000000000000 1.00000000000000000000000000000000" />
            </material>
        </visual>
        <collision>
            <origin rpy="0.00000000000000000000000000000000 1.57079632679489655799898173427209 -0.00000000000000000000000000000000" xyz="0.00000000000000000000000000000000 0.00000000000000000000000000000000 0.00000000000000000000000000000000"/>
            <geometry>
                <cylinder length="0.02849999999999999755750934582466" radius="0.00399999999999999661381977489327"/>
            </geometry>
        </collision>
    </link>
    <link name="FR_foot_link_b">
        <inertial>
            <origin rpy="0.00000000000000000000000000000000 -0.00000000000000000000000000000000 0.00000000000000000000000000000000" xyz="0.00000000000000000000000000000000 0.00000000000000000000000000000000 0.00000000000000000000000000000000"/>
            <mass value="0.01000000000000000020816681711722"/>
            <inertia ixx="0.00000006400000000000000398602185" ixy="0" ixz="0" iyy="0.00000006400000000000000398602185" iyz="0" izz="0.00000006400000000000000398602185"/>
        </inertial>
        <visual>
            <origin rpy="0.00000000000000000000000000000000 -0.00000000000000000000000000000000 0.00000000000000000000000000000000" xyz="0.00000000000000000000000000000000 0.00000000000000000000000000000000 0.00000000000000000000000000000000"/>
            <geometry>
                <sphere radius="0.00400000000000000008326672684689"/>
            </geometry>
            <material name="mat_21_0">
                <color rgba="1.00000000000000000000000000000000 1.00000000000000000000000000000000 1.00000000000000000000000000000000 1.00000000000000000000000000000000" />
            </material>
        </visual>
        <collision>
            <origin rpy="0.00000000000000000000000000000000 -0.00000000000000000000000000000000 0.00000000000000000000000000000000" xyz="0.00000000000000000000000000000000 0.00000000000000000000000000000000 0.00000000000000000000000000000000"/>
            <geometry>
                <sphere radius="0.00400000000000000008326672684689"/>
            </geometry>
        </collision>
    </link>
    <link name="HL_leg_origin">
        <inertial>
            <origin rpy="0.00000000000000000000000000000000 -0.00000000000000000000000000000000 0.00000000000000000000000000000000" xyz="0.00000000000000000000000000000000 0.00000000000000000000000000000000 0.00000000000000000000000000000000"/>
            <mass value="0.00200000000000000004163336342344"/>
            <inertia ixx="0.00000001280000000000000212069335" ixy="0" ixz="0" iyy="0.00000001280000000000000212069335" iyz="0" izz="0.00000001280000000000000212069335"/>
        </inertial>
        <visual>
            <origin rpy="0.00000000000000000000000000000000 -0.00000000000000000000000000000000 0.00000000000000000000000000000000" xyz="0.00000000000000000000000000000000 0.00000000000000000000000000000000 0.00000000000000000000000000000000"/>
            <geometry>
                <sphere radius="0.00400000000000000008326672684689"/>
            </geometry>
            <material name="mat_22_0">
                <color rgba="1.00000000000000000000000000000000 1.00000000000000000000000000000000 1.00000000000000000000000000000000 1.00000000000000000000000000000000" />
            </material>
        </visual>
        <collision>
            <origin rpy="0.00000000000000000000000000000000 -0.00000000000000000000000000000000 0.00000000000000000000000000000000" xyz="0.00000000000000000000000000000000 0.00000000000000000000000000000000 0.00000000000000000000000000000000"/>
            <geometry>
                <sphere radius="0.00400000000000000008326672684689"/>
            </geometry>
        </collision>
    </link>
    <link name="HL_hip_joint_a_link_fake"></link>
    <link name="HL_hip_link_a">
        <inertial>
            <origin rpy="0.00000000000000000000000000000000 -0.00000000000000000000000000000000 0.00000000000000000000000000000000" xyz="0.00000000000000000000000000000000 0.00000000000000000000000000000000 0.00000000000000000000000000000000"/>
            <mass value="0.02999999999999999888977697537484"/>
            <inertia ixx="0.00000031999999999999942436006823" ixy="0" ixz="0" iyy="0.00000092562499999999981980912259" iyz="0" izz="0.00000092562499999999981980912259"/>
        </inertial>
        <visual>
            <origin rpy="0.00000000000000000000000000000000 1.57079632679489655799898173427209 -0.00000000000000000000000000000000" xyz="0.00000000000000000000000000000000 0.00000000000000000000000000000000 0.00000000000000000000000000000000"/>
            <geometry>
                <cylinder length="0.01750000000000000166533453693773" radius="0.00400000000000000008326672684689"/>
            </geometry>
            <material name="mat_24_0">
                <color rgba="1.00000000000000000000000000000000 1.00000000000000000000000000000000 1.00000000000000000000000000000000 1.00000000000000000000000000000000" />
            </material>
        </visual>
        <collision>
            <origin rpy="0.00000000000000000000000000000000 1.57079632679489655799898173427209 -0.00000000000000000000000000000000" xyz="0.00000000000000000000000000000000 0.00000000000000000000000000000000 0.00000000000000000000000000000000"/>
            <geometry>
                <cylinder length="0.01750000000000000166533453693773" radius="0.00399999999999999661381977489327"/>
            </geometry>
        </collision>
    </link>
    <link name="HL_knee_joint_a_link_fake"></link>
    <link name="HL_knee_link_a">
        <inertial>
            <origin rpy="0.00000000000000000000000000000000 -0.00000000000000000000000000000000 0.00000000000000000000000000000000" xyz="0.00000000000000000000000000000000 0.00000000000000000000000000000000 0.00000000000000000000000000000000"/>
            <mass value="0.02999999999999999888977697537484"/>
            <inertia ixx="0.00000031999999999999942436006823" ixy="0" ixz="0" iyy="0.00000219062499999999946080999659" iyz="0" izz="0.00000219062499999999946080999659"/>
        </inertial>
        <visual>
            <origin rpy="0.00000000000000000000000000000000 1.57079632679489655799898173427209 -0.00000000000000000000000000000000" xyz="0.00000000000000000000000000000000 0.00000000000000000000000000000000 0.00000000000000000000000000000000"/>
            <geometry>
                <cylinder length="0.02850000000000000102695629777827" radius="0.00400000000000000008326672684689"/>
            </geometry>
            <material name="mat_26_0">
                <color rgba="1.00000000000000000000000000000000 1.00000000000000000000000000000000 1.00000000000000000000000000000000 1.00000000000000000000000000000000" />
            </material>
        </visual>
        <collision>
            <origin rpy="0.00000000000000000000000000000000 1.57079632679489655799898173427209 -0.00000000000000000000000000000000" xyz="0.00000000000000000000000000000000 0.00000000000000000000000000000000 0.00000000000000000000000000000000"/>
            <geometry>
                <cylinder length="0.02849999999999999755750934582466" radius="0.00399999999999999661381977489327"/>
            </geometry>
        </collision>
    </link>
    <link name="HL_foot_link_a">
        <inertial>
            <origin rpy="0.00000000000000000000000000000000 -0.00000000000000000000000000000000 0.00000000000000000000000000000000" xyz="0.00000000000000000000000000000000 0.00000000000000000000000000000000 0.00000000000000000000000000000000"/>
            <mass value="0.01000000000000000020816681711722"/>
            <inertia ixx="0.00000006400000000000000398602185" ixy="0" ixz="0" iyy="0.00000006400000000000000398602185" iyz="0" izz="0.00000006400000000000000398602185"/>
        </inertial>
        <visual>
            <origin rpy="0.00000000000000000000000000000000 -0.00000000000000000000000000000000 0.00000000000000000000000000000000" xyz="0.00000000000000000000000000000000 0.00000000000000000000000000000000 0.00000000000000000000000000000000"/>
            <geometry>
                <sphere radius="0.00400000000000000008326672684689"/>
            </geometry>
            <material name="mat_27_0">
                <color rgba="1.00000000000000000000000000000000 1.00000000000000000000000000000000 1.00000000000000000000000000000000 1.00000000000000000000000000000000" />
            </material>
        </visual>
        <collision>
            <origin rpy="0.00000000000000000000000000000000 -0.00000000000000000000000000000000 0.00000000000000000000000000000000" xyz="0.00000000000000000000000000000000 0.00000000000000000000000000000000 0.00000000000000000000000000000000"/>
            <geometry>
                <sphere radius="0.00400000000000000008326672684689"/>
            </geometry>
        </collision>
    </link>
    <link name="HL_hip_joint_b_link_fake"></link>
    <link name="HL_hip_link_b">
        <inertial>
            <origin rpy="0.00000000000000000000000000000000 -0.00000000000000000000000000000000 0.00000000000000000000000000000000" xyz="0.00000000000000000000000000000000 0.00000000000000000000000000000000 0.00000000000000000000000000000000"/>
            <mass value="0.02999999999999999888977697537484"/>
            <inertia ixx="0.00000031999999999999942436006823" ixy="0" ixz="0" iyy="0.00000092562499999999981980912259" iyz="0" izz="0.00000092562499999999981980912259"/>
        </inertial>
        <visual>
            <origin rpy="0.00000000000000000000000000000000 1.57079632679489655799898173427209 -0.00000000000000000000000000000000" xyz="0.00000000000000000000000000000000 0.00000000000000000000000000000000 0.00000000000000000000000000000000"/>
            <geometry>
                <cylinder length="0.01750000000000000166533453693773" radius="0.00400000000000000008326672684689"/>
            </geometry>
            <material name="mat_29_0">
                <color rgba="1.00000000000000000000000000000000 1.00000000000000000000000000000000 1.00000000000000000000000000000000 1.00000000000000000000000000000000" />
            </material>
        </visual>
        <collision>
            <origin rpy="0.00000000000000000000000000000000 1.57079632679489655799898173427209 -0.00000000000000000000000000000000" xyz="0.00000000000000000000000000000000 0.00000000000000000000000000000000 0.00000000000000000000000000000000"/>
            <geometry>
                <cylinder length="0.01750000000000000166533453693773" radius="0.00399999999999999661381977489327"/>
            </geometry>
        </collision>
    </link>
    <link name="HL_knee_joint_b_link_fake"></link>
    <link name="HL_knee_link_b">
        <inertial>
            <origin rpy="0.00000000000000000000000000000000 -0.00000000000000000000000000000000 0.00000000000000000000000000000000" xyz="0.00000000000000000000000000000000 0.00000000000000000000000000000000 0.00000000000000000000000000000000"/>
            <mass value="0.02999999999999999888977697537484"/>
            <inertia ixx="0.00000031999999999999942436006823" ixy="0" ixz="0" iyy="0.00000219062499999999946080999659" iyz="0" izz="0.00000219062499999999946080999659"/>
        </inertial>
        <visual>
            <origin rpy="0.00000000000000000000000000000000 1.57079632679489655799898173427209 -0.00000000000000000000000000000000" xyz="0.00000000000000000000000000000000 0.00000000000000000000000000000000 0.00000000000000000000000000000000"/>
            <geometry>
                <cylinder length="0.02850000000000000102695629777827" radius="0.00400000000000000008326672684689"/>
            </geometry>
            <material name="mat_31_0">
                <color rgba="1.00000000000000000000000000000000 1.00000000000000000000000000000000 1.00000000000000000000000000000000 1.00000000000000000000000000000000" />
            </material>
        </visual>
        <collision>
            <origin rpy="0.00000000000000000000000000000000 1.57079632679489655799898173427209 -0.00000000000000000000000000000000" xyz="0.00000000000000000000000000000000 0.00000000000000000000000000000000 0.00000000000000000000000000000000"/>
            <geometry>
                <cylinder length="0.02849999999999999755750934582466" radius="0.00399999999999999661381977489327"/>
            </geometry>
        </collision>
    </link>
    <link name="HL_foot_link_b">
        <inertial>
            <origin rpy="0.00000000000000000000000000000000 -0.00000000000000000000000000000000 0.00000000000000000000000000000000" xyz="0.00000000000000000000000000000000 0.00000000000000000000000000000000 0.00000000000000000000000000000000"/>
            <mass value="0.01000000000000000020816681711722"/>
            <inertia ixx="0.00000006400000000000000398602185" ixy="0" ixz="0" iyy="0.00000006400000000000000398602185" iyz="0" izz="0.00000006400000000000000398602185"/>
        </inertial>
        <visual>
            <origin rpy="0.00000000000000000000000000000000 -0.00000000000000000000000000000000 0.00000000000000000000000000000000" xyz="0.00000000000000000000000000000000 0.00000000000000000000000000000000 0.00000000000000000000000000000000"/>
            <geometry>
                <sphere radius="0.00400000000000000008326672684689"/>
            </geometry>
            <material name="mat_32_0">
                <color rgba="1.00000000000000000000000000000000 1.00000000000000000000000000000000 1.00000000000000000000000000000000 1.00000000000000000000000000000000" />
            </material>
        </visual>
        <collision>
            <origin rpy="0.00000000000000000000000000000000 -0.00000000000000000000000000000000 0.00000000000000000000000000000000" xyz="0.00000000000000000000000000000000 0.00000000000000000000000000000000 0.00000000000000000000000000000000"/>
            <geometry>
                <sphere radius="0.00400000000000000008326672684689"/>
            </geometry>
        </collision>
    </link>
    <link name="HR_leg_origin">
        <inertial>
            <origin rpy="0.00000000000000000000000000000000 -0.00000000000000000000000000000000 0.00000000000000000000000000000000" xyz="0.00000000000000000000000000000000 0.00000000000000000000000000000000 0.00000000000000000000000000000000"/>
            <mass value="0.00200000000000000004163336342344"/>
            <inertia ixx="0.00000001280000000000000212069335" ixy="0" ixz="0" iyy="0.00000001280000000000000212069335" iyz="0" izz="0.00000001280000000000000212069335"/>
        </inertial>
        <visual>
            <origin rpy="0.00000000000000000000000000000000 -0.00000000000000000000000000000000 0.00000000000000000000000000000000" xyz="0.00000000000000000000000000000000 0.00000000000000000000000000000000 0.00000000000000000000000000000000"/>
            <geometry>
                <sphere radius="0.00400000000000000008326672684689"/>
            </geometry>
            <material name="mat_33_0">
                <color rgba="1.00000000000000000000000000000000 1.00000000000000000000000000000000 1.00000000000000000000000000000000 1.00000000000000000000000000000000" />
            </material>
        </visual>
        <collision>
            <origin rpy="0.00000000000000000000000000000000 -0.00000000000000000000000000000000 0.00000000000000000000000000000000" xyz="0.00000000000000000000000000000000 0.00000000000000000000000000000000 0.00000000000000000000000000000000"/>
            <geometry>
                <sphere radius="0.00400000000000000008326672684689"/>
            </geometry>
        </collision>
    </link>
    <link name="HR_hip_joint_a_link_fake"></link>
    <link name="HR_hip_link_a">
        <inertial>
            <origin rpy="0.00000000000000000000000000000000 -0.00000000000000000000000000000000 0.00000000000000000000000000000000" xyz="0.00000000000000000000000000000000 0.00000000000000000000000000000000 0.00000000000000000000000000000000"/>
            <mass value="0.02999999999999999888977697537484"/>
            <inertia ixx="0.00000031999999999999942436006823" ixy="0" ixz="0" iyy="0.00000092562499999999981980912259" iyz="0" izz="0.00000092562499999999981980912259"/>
        </inertial>
        <visual>
            <origin rpy="0.00000000000000000000000000000000 1.57079632679489655799898173427209 -0.00000000000000000000000000000000" xyz="0.00000000000000000000000000000000 0.00000000000000000000000000000000 0.00000000000000000000000000000000"/>
            <geometry>
                <cylinder length="0.01750000000000000166533453693773" radius="0.00400000000000000008326672684689"/>
            </geometry>
            <material name="mat_35_0">
                <color rgba="1.00000000000000000000000000000000 1.00000000000000000000000000000000 1.00000000000000000000000000000000 1.00000000000000000000000000000000" />
            </material>
        </visual>
        <collision>
            <origin rpy="0.00000000000000000000000000000000 1.57079632679489655799898173427209 -0.00000000000000000000000000000000" xyz="0.00000000000000000000000000000000 0.00000000000000000000000000000000 0.00000000000000000000000000000000"/>
            <geometry>
                <cylinder length="0.01750000000000000166533453693773" radius="0.00399999999999999661381977489327"/>
            </geometry>
        </collision>
    </link>
    <link name="HR_knee_joint_a_link_fake"></link>
    <link name="HR_knee_link_a">
        <inertial>
            <origin rpy="0.00000000000000000000000000000000 -0.00000000000000000000000000000000 0.00000000000000000000000000000000" xyz="0.00000000000000000000000000000000 0.00000000000000000000000000000000 0.00000000000000000000000000000000"/>
            <mass value="0.02999999999999999888977697537484"/>
            <inertia ixx="0.00000031999999999999942436006823" ixy="0" ixz="0" iyy="0.00000219062499999999946080999659" iyz="0" izz="0.00000219062499999999946080999659"/>
        </inertial>
        <visual>
            <origin rpy="0.00000000000000000000000000000000 1.57079632679489655799898173427209 -0.00000000000000000000000000000000" xyz="0.00000000000000000000000000000000 0.00000000000000000000000000000000 0.00000000000000000000000000000000"/>
            <geometry>
                <cylinder length="0.02850000000000000102695629777827" radius="0.00400000000000000008326672684689"/>
            </geometry>
            <material name="mat_37_0">
                <color rgba="1.00000000000000000000000000000000 1.00000000000000000000000000000000 1.00000000000000000000000000000000 1.00000000000000000000000000000000" />
            </material>
        </visual>
        <collision>
            <origin rpy="0.00000000000000000000000000000000 1.57079632679489655799898173427209 -0.00000000000000000000000000000000" xyz="0.00000000000000000000000000000000 0.00000000000000000000000000000000 0.00000000000000000000000000000000"/>
            <geometry>
                <cylinder length="0.02849999999999999755750934582466" radius="0.00399999999999999661381977489327"/>
            </geometry>
        </collision>
    </link>
    <link name="HR_foot_link_a">
        <inertial>
            <origin rpy="0.00000000000000000000000000000000 -0.00000000000000000000000000000000 0.00000000000000000000000000000000" xyz="0.00000000000000000000000000000000 0.00000000000000000000000000000000 0.00000000000000000000000000000000"/>
            <mass value="0.01000000000000000020816681711722"/>
            <inertia ixx="0.00000006400000000000000398602185" ixy="0" ixz="0" iyy="0.00000006400000000000000398602185" iyz="0" izz="0.00000006400000000000000398602185"/>
        </inertial>
        <visual>
            <origin rpy="0.00000000000000000000000000000000 -0.00000000000000000000000000000000 0.00000000000000000000000000000000" xyz="0.00000000000000000000000000000000 0.00000000000000000000000000000000 0.00000000000000000000000000000000"/>
            <geometry>
                <sphere radius="0.00400000000000000008326672684689"/>
            </geometry>
            <material name="mat_38_0">
                <color rgba="1.00000000000000000000000000000000 1.00000000000000000000000000000000 1.00000000000000000000000000000000 1.00000000000000000000000000000000" />
            </material>
        </visual>
        <collision>
            <origin rpy="0.00000000000000000000000000000000 -0.00000000000000000000000000000000 0.00000000000000000000000000000000" xyz="0.00000000000000000000000000000000 0.00000000000000000000000000000000 0.00000000000000000000000000000000"/>
            <geometry>
                <sphere radius="0.00400000000000000008326672684689"/>
            </geometry>
        </collision>
    </link>
    <link name="HR_hip_joint_b_link_fake"></link>
    <link name="HR_hip_link_b">
        <inertial>
            <origin rpy="0.00000000000000000000000000000000 -0.00000000000000000000000000000000 0.00000000000000000000000000000000" xyz="0.00000000000000000000000000000000 0.00000000000000000000000000000000 0.00000000000000000000000000000000"/>
            <mass value="0.02999999999999999888977697537484"/>
            <inertia ixx="0.00000031999999999999942436006823" ixy="0" ixz="0" iyy="0.00000092562499999999981980912259" iyz="0" izz="0.00000092562499999999981980912259"/>
        </inertial>
        <visual>
            <origin rpy="0.00000000000000000000000000000000 1.57079632679489655799898173427209 -0.00000000000000000000000000000000" xyz="0.00000000000000000000000000000000 0.00000000000000000000000000000000 0.00000000000000000000000000000000"/>
            <geometry>
                <cylinder length="0.01750000000000000166533453693773" radius="0.00400000000000000008326672684689"/>
            </geometry>
            <material name="mat_40_0">
                <color rgba="1.00000000000000000000000000000000 1.00000000000000000000000000000000 1.00000000000000000000000000000000 1.00000000000000000000000000000000" />
            </material>
        </visual>
        <collision>
            <origin rpy="0.00000000000000000000000000000000 1.57079632679489655799898173427209 -0.00000000000000000000000000000000" xyz="0.00000000000000000000000000000000 0.00000000000000000000000000000000 0.00000000000000000000000000000000"/>
            <geometry>
                <cylinder length="0.01750000000000000166533453693773" radius="0.00399999999999999661381977489327"/>
            </geometry>
        </collision>
    </link>
    <link name="HR_knee_joint_b_link_fake"></link>
    <link name="HR_knee_link_b">
        <inertial>
            <origin rpy="0.00000000000000000000000000000000 -0.00000000000000000000000000000000 0.00000000000000000000000000000000" xyz="0.00000000000000000000000000000000 0.00000000000000000000000000000000 0.00000000000000000000000000000000"/>
            <mass value="0.02999999999999999888977697537484"/>
            <inertia ixx="0.00000031999999999999942436006823" ixy="0" ixz="0" iyy="0.00000219062499999999946080999659" iyz="0" izz="0.00000219062499999999946080999659"/>
        </inertial>
        <visual>
            <origin rpy="0.00000000000000000000000000000000 1.57079632679489655799898173427209 -0.00000000000000000000000000000000" xyz="0.00000000000000000000000000000000 0.00000000000000000000000000000000 0.00000000000000000000000000000000"/>
            <geometry>
                <cylinder length="0.02850000000000000102695629777827" radius="0.00400000000000000008326672684689"/>
            </geometry>
            <material name="mat_42_0">
                <color rgba="1.00000000000000000000000000000000 1.00000000000000000000000000000000 1.00000000000000000000000000000000 1.00000000000000000000000000000000" />
            </material>
        </visual>
        <collision>
            <origin rpy="0.00000000000000000000000000000000 1.57079632679489655799898173427209 -0.00000000000000000000000000000000" xyz="0.00000000000000000000000000000000 0.00000000000000000000000000000000 0.00000000000000000000000000000000"/>
            <geometry>
                <cylinder length="0.02849999999999999755750934582466" radius="0.00399999999999999661381977489327"/>
            </geometry>
        </collision>
    </link>
    <link name="HR_foot_link_b">
        <inertial>
            <origin rpy="0.00000000000000000000000000000000 -0.00000000000000000000000000000000 0.00000000000000000000000000000000" xyz="0.00000000000000000000000000000000 0.00000000000000000000000000000000 0.00000000000000000000000000000000"/>
            <mass value="0.01000000000000000020816681711722"/>
            <inertia ixx="0.00000006400000000000000398602185" ixy="0" ixz="0" iyy="0.00000006400000000000000398602185" iyz="0" izz="0.00000006400000000000000398602185"/>
        </inertial>
        <visual>
            <origin rpy="0.00000000000000000000000000000000 -0.00000000000000000000000000000000 0.00000000000000000000000000000000" xyz="0.00000000000000000000000000000000 0.00000000000000000000000000000000 0.00000000000000000000000000000000"/>
            <geometry>
                <sphere radius="0.00400000000000000008326672684689"/>
            </geometry>
            <material name="mat_43_0">
                <color rgba="1.00000000000000000000000000000000 1.00000000000000000000000000000000 1.00000000000000000000000000000000 1.00000000000000000000000000000000" />
            </material>
        </visual>
        <collision>
            <origin rpy="0.00000000000000000000000000000000 -0.00000000000000000000000000000000 0.00000000000000000000000000000000" xyz="0.00000000000000000000000000000000 0.00000000000000000000000000000000 0.00000000000000000000000000000000"/>
            <geometry>
                <sphere radius="0.00400000000000000008326672684689"/>
            </geometry>
        </collision>
    </link>
    <joint name="FL_leg_origin_joint" type="fixed">
        <parent link="body"/>
        <child link="FL_leg_origin"/>
        <origin rpy="-1.57079632679489655799898173427209 0.00000000000000000000000000000000 0.00000000000000000000000000000000" xyz="0.04141800105571746826171875000000 0.04250000044703483581542968750000 -0.01014799997210502624511718750000"/>
        <axis xyz="0.00000000000000000000000000000000 0.00000000000000000000000000000000 0.00000000000000000000000000000000"/>
    </joint>
    <joint name="FL_hip_joint_a" type="continuous">
        <parent link="FL_leg_origin"/>
        <child link="FL_hip_joint_a_link_fake"/>
        <origin rpy="0.00000000000000000000000000000000 -0.00000000000000000000000000000000 0.00000000000000000000000000000000" xyz="0.01099999994039535522460937500000 0.00000000000000000000000000000000 0.00000000000000000000000000000000"/>
        <axis xyz="0.00000000000000000000000000000000 0.00000000000000000000000000000000 -1.00000000000000000000000000000000"/>
    </joint>
    <joint name="FL_hip_joint_a_joint_fake" type="fixed">
        <parent link="FL_hip_joint_a_link_fake"/>
        <child link="FL_hip_link_a"/>
        <origin rpy="0.00000000000000000000000000000000 -0.00000000000000000000000000000000 0.00000000000000000000000000000000" xyz="0.00875000003725290298461914062500 0.00000000000000000000000000000000 0.00000000000000000000000000000000"/>
        <axis xyz="0.00000000000000000000000000000000 0.00000000000000000000000000000000 0.00000000000000000000000000000000"/>
    </joint>
    <joint name="FL_knee_joint_a" type="continuous">
        <parent link="FL_hip_link_a"/>
        <child link="FL_knee_joint_a_link_fake"/>
        <origin rpy="0.00000000000000000000000000000000 -0.00000000000000000000000000000000 3.14159265358979311599796346854419" xyz="0.00875000003725290298461914062500 0.00000000000000000000000000000000 0.00000000000000000000000000000000"/>
        <axis xyz="0.00000000000000000000000000000000 0.00000000000000000000000000000000 -1.00000000000000000000000000000000"/>
    </joint>
    <joint name="FL_knee_joint_a_joint_fake" type="fixed">
        <parent link="FL_knee_joint_a_link_fake"/>
        <child link="FL_knee_link_a"/>
        <origin rpy="0.00000000000000000000000000000000 -0.00000000000000000000000000000000 0.00000000000000000000000000000000" xyz="0.01425000000745058059692382812500 0.00000000000000000000000000000000 0.00000000000000000000000000000000"/>
        <axis xyz="0.00000000000000000000000000000000 0.00000000000000000000000000000000 0.00000000000000000000000000000000"/>
    </joint>
    <joint name="FL_foot_joint_a" type="revolute">
        <parent link="FL_knee_link_a"/>
        <child link="FL_foot_link_a"/>
        <limit lower="0.0" upper="0.0" effort="-1" velocity="-1"/>
        <origin rpy="0.00000000000000000000000000000000 -0.00000000000000000000000000000000 0.00000000000000000000000000000000" xyz="0.01425000000745058059692382812500 0.00000000000000000000000000000000 0.00000000000000000000000000000000"/>
        <axis xyz="0.00000000000000000000000000000000 0.00000000000000000000000000000000 0.00000000000000000000000000000000"/>
    </joint>
    <joint name="FL_hip_joint_b" type="continuous">
        <parent link="FL_leg_origin"/>
        <child link="FL_hip_joint_b_link_fake"/>
        <origin rpy="3.14159265358979311599796346854419 0.00000000000000012246468525851679 3.14159265358979311599796346854419" xyz="-0.01099999994039535522460937500000 0.00000000000000000000000000000000 0.00000000000000000000000000000000"/>
        <axis xyz="0.00000000000000000000000000000000 0.00000000000000000000000000000000 -1.00000000000000000000000000000000"/>
    </joint>
    <joint name="FL_hip_joint_b_joint_fake" type="fixed">
        <parent link="FL_hip_joint_b_link_fake"/>
        <child link="FL_hip_link_b"/>
        <origin rpy="0.00000000000000000000000000000000 -0.00000000000000000000000000000000 0.00000000000000000000000000000000" xyz="0.00875000003725290298461914062500 0.00000000000000000000000000000000 0.00000000000000000000000000000000"/>
        <axis xyz="0.00000000000000000000000000000000 0.00000000000000000000000000000000 0.00000000000000000000000000000000"/>
    </joint>
    <joint name="FL_knee_joint_b" type="continuous">
        <parent link="FL_hip_link_b"/>
        <child link="FL_knee_joint_b_link_fake"/>
        <origin rpy="0.00000000000000000000000000000000 -0.00000000000000000000000000000000 3.14159265358979311599796346854419" xyz="0.00875000003725290298461914062500 0.00000000000000000000000000000000 0.00000000000000000000000000000000"/>
        <axis xyz="0.00000000000000000000000000000000 0.00000000000000000000000000000000 -1.00000000000000000000000000000000"/>
    </joint>
    <joint name="FL_knee_joint_b_joint_fake" type="fixed">
        <parent link="FL_knee_joint_b_link_fake"/>
        <child link="FL_knee_link_b"/>
        <origin rpy="0.00000000000000000000000000000000 -0.00000000000000000000000000000000 0.00000000000000000000000000000000" xyz="0.01425000000745058059692382812500 0.00000000000000000000000000000000 0.00000000000000000000000000000000"/>
        <axis xyz="0.00000000000000000000000000000000 0.00000000000000000000000000000000 0.00000000000000000000000000000000"/>
    </joint>
    <joint name="FL_foot_joint_b" type="revolute">
        <parent link="FL_knee_link_b"/>
        <child link="FL_foot_link_b"/>
        <limit lower="0.0" upper="0.0" effort="-1" velocity="-1"/>

        <origin rpy="0.00000000000000000000000000000000 -0.00000000000000000000000000000000 0.00000000000000000000000000000000" xyz="0.01425000000745058059692382812500 0.00000000000000000000000000000000 0.00000000000000000000000000000000"/>
        <axis xyz="0.00000000000000000000000000000000 0.00000000000000000000000000000000 0.00000000000000000000000000000000"/>
    </joint>
    <joint name="FR_leg_origin_joint" type="fixed">
        <parent link="body"/>
        <child link="FR_leg_origin"/>
        <origin rpy="-1.57079632679489655799898173427209 -0.00000000000000000000000000000000 3.14159265358979311599796346854419" xyz="0.04141800105571746826171875000000 -0.04250000044703483581542968750000 -0.01014799997210502624511718750000"/>
        <axis xyz="0.00000000000000000000000000000000 0.00000000000000000000000000000000 0.00000000000000000000000000000000"/>
    </joint>
    <joint name="FR_hip_joint_a" type="continuous">
        <parent link="FR_leg_origin"/>
        <child link="FR_hip_joint_a_link_fake"/>
        <origin rpy="0.00000000000000000000000000000000 -0.00000000000000000000000000000000 0.00000000000000000000000000000000" xyz="0.01099999994039535522460937500000 0.00000000000000000000000000000000 0.00000000000000000000000000000000"/>
        <axis xyz="0.00000000000000000000000000000000 0.00000000000000000000000000000000 -1.00000000000000000000000000000000"/>
    </joint>
    <joint name="FR_hip_joint_a_joint_fake" type="fixed">
        <parent link="FR_hip_joint_a_link_fake"/>
        <child link="FR_hip_link_a"/>
        <origin rpy="0.00000000000000000000000000000000 -0.00000000000000000000000000000000 0.00000000000000000000000000000000" xyz="0.00875000003725290298461914062500 0.00000000000000000000000000000000 0.00000000000000000000000000000000"/>
        <axis xyz="0.00000000000000000000000000000000 0.00000000000000000000000000000000 0.00000000000000000000000000000000"/>
    </joint>
    <joint name="FR_knee_joint_a" type="continuous">
        <parent link="FR_hip_link_a"/>
        <child link="FR_knee_joint_a_link_fake"/>
        <origin rpy="0.00000000000000000000000000000000 -0.00000000000000000000000000000000 3.14159265358979311599796346854419" xyz="0.00875000003725290298461914062500 0.00000000000000000000000000000000 0.00000000000000000000000000000000"/>
        <axis xyz="0.00000000000000000000000000000000 0.00000000000000000000000000000000 -1.00000000000000000000000000000000"/>
    </joint>
    <joint name="FR_knee_joint_a_joint_fake" type="fixed">
        <parent link="FR_knee_joint_a_link_fake"/>
        <child link="FR_knee_link_a"/>
        <origin rpy="0.00000000000000000000000000000000 -0.00000000000000000000000000000000 0.00000000000000000000000000000000" xyz="0.01425000000745058059692382812500 0.00000000000000000000000000000000 0.00000000000000000000000000000000"/>
        <axis xyz="0.00000000000000000000000000000000 0.00000000000000000000000000000000 0.00000000000000000000000000000000"/>
    </joint>
    <joint name="FR_foot_joint_a" type="revolute">
        <parent link="FR_knee_link_a"/>
        <child link="FR_foot_link_a"/>
        <limit lower="0.0" upper="0.0" effort="-1" velocity="-1"/>

        <origin rpy="0.00000000000000000000000000000000 -0.00000000000000000000000000000000 0.00000000000000000000000000000000" xyz="0.01425000000745058059692382812500 0.00000000000000000000000000000000 0.00000000000000000000000000000000"/>
        <axis xyz="0.00000000000000000000000000000000 0.00000000000000000000000000000000 0.00000000000000000000000000000000"/>
    </joint>
    <joint name="FR_hip_joint_b" type="continuous">
        <parent link="FR_leg_origin"/>
        <child link="FR_hip_joint_b_link_fake"/>
        <origin rpy="3.14159265358979311599796346854419 0.00000000000000012246468525851679 3.14159265358979311599796346854419" xyz="-0.01099999994039535522460937500000 0.00000000000000000000000000000000 0.00000000000000000000000000000000"/>
        <axis xyz="0.00000000000000000000000000000000 0.00000000000000000000000000000000 -1.00000000000000000000000000000000"/>
    </joint>
    <joint name="FR_hip_joint_b_joint_fake" type="fixed">
        <parent link="FR_hip_joint_b_link_fake"/>
        <child link="FR_hip_link_b"/>
        <origin rpy="0.00000000000000000000000000000000 -0.00000000000000000000000000000000 0.00000000000000000000000000000000" xyz="0.00875000003725290298461914062500 0.00000000000000000000000000000000 0.00000000000000000000000000000000"/>
        <axis xyz="0.00000000000000000000000000000000 0.00000000000000000000000000000000 0.00000000000000000000000000000000"/>
    </joint>
    <joint name="FR_knee_joint_b" type="continuous">
        <parent link="FR_hip_link_b"/>
        <child link="FR_knee_joint_b_link_fake"/>
        <origin rpy="0.00000000000000000000000000000000 -0.00000000000000000000000000000000 3.14159265358979311599796346854419" xyz="0.00875000003725290298461914062500 0.00000000000000000000000000000000 0.00000000000000000000000000000000"/>
        <axis xyz="0.00000000000000000000000000000000 0.00000000000000000000000000000000 -1.00000000000000000000000000000000"/>
    </joint>
    <joint name="FR_knee_joint_b_joint_fake" type="fixed">
        <parent link="FR_knee_joint_b_link_fake"/>
        <child link="FR_knee_link_b"/>
        <origin rpy="0.00000000000000000000000000000000 -0.00000000000000000000000000000000 0.00000000000000000000000000000000" xyz="0.01425000000745058059692382812500 0.00000000000000000000000000000000 0.00000000000000000000000000000000"/>
        <axis xyz="0.00000000000000000000000000000000 0.00000000000000000000000000000000 0.00000000000000000000000000000000"/>
    </joint>
    <joint name="FR_foot_joint_b" type="revolute">
        <parent link="FR_knee_link_b"/>
        <child link="FR_foot_link_b"/>
        <limit lower="0.0" upper="0.0" effort="-1" velocity="-1"/>

        <origin rpy="0.00000000000000000000000000000000 -0.00000000000000000000000000000000 0.00000000000000000000000000000000" xyz="0.01425000000745058059692382812500 0.00000000000000000000000000000000 0.00000000000000000000000000000000"/>
        <axis xyz="0.00000000000000000000000000000000 0.00000000000000000000000000000000 0.00000000000000000000000000000000"/>
    </joint>
    <joint name="HL_leg_origin_joint" type="fixed">
        <parent link="body"/>
        <child link="HL_leg_origin"/>
        <origin rpy="-1.57079632679489655799898173427209 0.00000000000000000000000000000000 0.00000000000000000000000000000000" xyz="-0.04141800105571746826171875000000 0.04250000044703483581542968750000 -0.01014799997210502624511718750000"/>
        <axis xyz="0.00000000000000000000000000000000 0.00000000000000000000000000000000 0.00000000000000000000000000000000"/>
    </joint>
    <joint name="HL_hip_joint_a" type="continuous">
        <parent link="HL_leg_origin"/>
        <child link="HL_hip_joint_a_link_fake"/>
        <origin rpy="0.00000000000000000000000000000000 -0.00000000000000000000000000000000 0.00000000000000000000000000000000" xyz="0.01099999994039535522460937500000 0.00000000000000000000000000000000 0.00000000000000000000000000000000"/>
        <axis xyz="0.00000000000000000000000000000000 0.00000000000000000000000000000000 -1.00000000000000000000000000000000"/>
    </joint>
    <joint name="HL_hip_joint_a_joint_fake" type="fixed">
        <parent link="HL_hip_joint_a_link_fake"/>
        <child link="HL_hip_link_a"/>
        <origin rpy="0.00000000000000000000000000000000 -0.00000000000000000000000000000000 0.00000000000000000000000000000000" xyz="0.00875000003725290298461914062500 0.00000000000000000000000000000000 0.00000000000000000000000000000000"/>
        <axis xyz="0.00000000000000000000000000000000 0.00000000000000000000000000000000 0.00000000000000000000000000000000"/>
    </joint>
    <joint name="HL_knee_joint_a" type="continuous">
        <parent link="HL_hip_link_a"/>
        <child link="HL_knee_joint_a_link_fake"/>
        <origin rpy="0.00000000000000000000000000000000 -0.00000000000000000000000000000000 3.14159265358979311599796346854419" xyz="0.00875000003725290298461914062500 0.00000000000000000000000000000000 0.00000000000000000000000000000000"/>
        <axis xyz="0.00000000000000000000000000000000 0.00000000000000000000000000000000 -1.00000000000000000000000000000000"/>
    </joint>
    <joint name="HL_knee_joint_a_joint_fake" type="fixed">
        <parent link="HL_knee_joint_a_link_fake"/>
        <child link="HL_knee_link_a"/>
        <origin rpy="0.00000000000000000000000000000000 -0.00000000000000000000000000000000 0.00000000000000000000000000000000" xyz="0.01425000000745058059692382812500 0.00000000000000000000000000000000 0.00000000000000000000000000000000"/>
        <axis xyz="0.00000000000000000000000000000000 0.00000000000000000000000000000000 0.00000000000000000000000000000000"/>
    </joint>
    <joint name="HL_foot_joint_a" type="revolute">
        <parent link="HL_knee_link_a"/>
        <child link="HL_foot_link_a"/>
        <limit lower="0.0" upper="0.0" effort="-1" velocity="-1"/>

        <origin rpy="0.00000000000000000000000000000000 -0.00000000000000000000000000000000 0.00000000000000000000000000000000" xyz="0.01425000000745058059692382812500 0.00000000000000000000000000000000 0.00000000000000000000000000000000"/>
        <axis xyz="0.00000000000000000000000000000000 0.00000000000000000000000000000000 0.00000000000000000000000000000000"/>
    </joint>
    <joint name="HL_hip_joint_b" type="continuous">
        <parent link="HL_leg_origin"/>
        <child link="HL_hip_joint_b_link_fake"/>
        <origin rpy="3.14159265358979311599796346854419 0.00000000000000012246468525851679 3.14159265358979311599796346854419" xyz="-0.01099999994039535522460937500000 0.00000000000000000000000000000000 0.00000000000000000000000000000000"/>
        <axis xyz="0.00000000000000000000000000000000 0.00000000000000000000000000000000 -1.00000000000000000000000000000000"/>
    </joint>
    <joint name="HL_hip_joint_b_joint_fake" type="fixed">
        <parent link="HL_hip_joint_b_link_fake"/>
        <child link="HL_hip_link_b"/>
        <origin rpy="0.00000000000000000000000000000000 -0.00000000000000000000000000000000 0.00000000000000000000000000000000" xyz="0.00875000003725290298461914062500 0.00000000000000000000000000000000 0.00000000000000000000000000000000"/>
        <axis xyz="0.00000000000000000000000000000000 0.00000000000000000000000000000000 0.00000000000000000000000000000000"/>
    </joint>
    <joint name="HL_knee_joint_b" type="continuous">
        <parent link="HL_hip_link_b"/>
        <child link="HL_knee_joint_b_link_fake"/>
        <origin rpy="0.00000000000000000000000000000000 -0.00000000000000000000000000000000 3.14159265358979311599796346854419" xyz="0.00875000003725290298461914062500 0.00000000000000000000000000000000 0.00000000000000000000000000000000"/>
        <axis xyz="0.00000000000000000000000000000000 0.00000000000000000000000000000000 -1.00000000000000000000000000000000"/>
    </joint>
    <joint name="HL_knee_joint_b_joint_fake" type="fixed">
        <parent link="HL_knee_joint_b_link_fake"/>
        <child link="HL_knee_link_b"/>
        <origin rpy="0.00000000000000000000000000000000 -0.00000000000000000000000000000000 0.00000000000000000000000000000000" xyz="0.01425000000745058059692382812500 0.00000000000000000000000000000000 0.00000000000000000000000000000000"/>
        <axis xyz="0.00000000000000000000000000000000 0.00000000000000000000000000000000 0.00000000000000000000000000000000"/>
    </joint>
    <joint name="HL_foot_joint_b" type="revolute">
        <parent link="HL_knee_link_b"/>
        <child link="HL_foot_link_b"/>
        <limit lower="0.0" upper="0.0" effort="-1" velocity="-1"/>

        <origin rpy="0.00000000000000000000000000000000 -0.00000000000000000000000000000000 0.00000000000000000000000000000000" xyz="0.01425000000745058059692382812500 0.00000000000000000000000000000000 0.00000000000000000000000000000000"/>
        <axis xyz="0.00000000000000000000000000000000 0.00000000000000000000000000000000 0.00000000000000000000000000000000"/>
    </joint>
    <joint name="HR_leg_origin_joint" type="fixed">
        <parent link="body"/>
        <child link="HR_leg_origin"/>
        <origin rpy="-1.57079632679489655799898173427209 -0.00000000000000000000000000000000 3.14159265358979311599796346854419" xyz="-0.04141800105571746826171875000000 -0.04250000044703483581542968750000 -0.01014799997210502624511718750000"/>
        <axis xyz="0.00000000000000000000000000000000 0.00000000000000000000000000000000 0.00000000000000000000000000000000"/>
    </joint>
    <joint name="HR_hip_joint_a" type="continuous">
        <parent link="HR_leg_origin"/>
        <child link="HR_hip_joint_a_link_fake"/>
        <origin rpy="0.00000000000000000000000000000000 -0.00000000000000000000000000000000 0.00000000000000000000000000000000" xyz="0.01099999994039535522460937500000 0.00000000000000000000000000000000 0.00000000000000000000000000000000"/>
        <axis xyz="0.00000000000000000000000000000000 0.00000000000000000000000000000000 -1.00000000000000000000000000000000"/>
    </joint>
    <joint name="HR_hip_joint_a_joint_fake" type="fixed">
        <parent link="HR_hip_joint_a_link_fake"/>
        <child link="HR_hip_link_a"/>
        <origin rpy="0.00000000000000000000000000000000 -0.00000000000000000000000000000000 0.00000000000000000000000000000000" xyz="0.00875000003725290298461914062500 0.00000000000000000000000000000000 0.00000000000000000000000000000000"/>
        <axis xyz="0.00000000000000000000000000000000 0.00000000000000000000000000000000 0.00000000000000000000000000000000"/>
    </joint>
    <joint name="HR_knee_joint_a" type="continuous">
        <parent link="HR_hip_link_a"/>
        <child link="HR_knee_joint_a_link_fake"/>
        <origin rpy="0.00000000000000000000000000000000 -0.00000000000000000000000000000000 3.14159265358979311599796346854419" xyz="0.00875000003725290298461914062500 0.00000000000000000000000000000000 0.00000000000000000000000000000000"/>
        <axis xyz="0.00000000000000000000000000000000 0.00000000000000000000000000000000 -1.00000000000000000000000000000000"/>
    </joint>
    <joint name="HR_knee_joint_a_joint_fake" type="fixed">
        <parent link="HR_knee_joint_a_link_fake"/>
        <child link="HR_knee_link_a"/>
        <origin rpy="0.00000000000000000000000000000000 -0.00000000000000000000000000000000 0.00000000000000000000000000000000" xyz="0.01425000000745058059692382812500 0.00000000000000000000000000000000 0.00000000000000000000000000000000"/>
        <axis xyz="0.00000000000000000000000000000000 0.00000000000000000000000000000000 0.00000000000000000000000000000000"/>
    </joint>
    <joint name="HR_foot_joint_a" type="revolute">
        <parent link="HR_knee_link_a"/>
        <child link="HR_foot_link_a"/>
        <limit lower="0.0" upper="0.0" effort="-1" velocity="-1"/>

        <origin rpy="0.00000000000000000000000000000000 -0.00000000000000000000000000000000 0.00000000000000000000000000000000" xyz="0.01425000000745058059692382812500 0.00000000000000000000000000000000 0.00000000000000000000000000000000"/>
        <axis xyz="0.00000000000000000000000000000000 0.00000000000000000000000000000000 0.00000000000000000000000000000000"/>
    </joint>
    <joint name="HR_hip_joint_b" type="continuous">
        <parent link="HR_leg_origin"/>
        <child link="HR_hip_joint_b_link_fake"/>
        <origin rpy="3.14159265358979311599796346854419 0.00000000000000012246468525851679 3.14159265358979311599796346854419" xyz="-0.01099999994039535522460937500000 0.00000000000000000000000000000000 0.00000000000000000000000000000000"/>
        <axis xyz="0.00000000000000000000000000000000 0.00000000000000000000000000000000 -1.00000000000000000000000000000000"/>
    </joint>
    <joint name="HR_hip_joint_b_joint_fake" type="fixed">
        <parent link="HR_hip_joint_b_link_fake"/>
        <child link="HR_hip_link_b"/>
        <origin rpy="0.00000000000000000000000000000000 -0.00000000000000000000000000000000 0.00000000000000000000000000000000" xyz="0.00875000003725290298461914062500 0.00000000000000000000000000000000 0.00000000000000000000000000000000"/>
        <axis xyz="0.00000000000000000000000000000000 0.00000000000000000000000000000000 0.00000000000000000000000000000000"/>
    </joint>
    <joint name="HR_knee_joint_b" type="continuous">
        <parent link="HR_hip_link_b"/>
        <child link="HR_knee_joint_b_link_fake"/>
        <origin rpy="0.00000000000000000000000000000000 -0.00000000000000000000000000000000 3.14159265358979311599796346854419" xyz="0.00875000003725290298461914062500 0.00000000000000000000000000000000 0.00000000000000000000000000000000"/>
        <axis xyz="0.00000000000000000000000000000000 0.00000000000000000000000000000000 -1.00000000000000000000000000000000"/>
    </joint>
    <joint name="HR_knee_joint_b_joint_fake" type="fixed">
        <parent link="HR_knee_joint_b_link_fake"/>
        <child link="HR_knee_link_b"/>
        <origin rpy="0.00000000000000000000000000000000 -0.00000000000000000000000000000000 0.00000000000000000000000000000000" xyz="0.01425000000745058059692382812500 0.00000000000000000000000000000000 0.00000000000000000000000000000000"/>
        <axis xyz="0.00000000000000000000000000000000 0.00000000000000000000000000000000 0.00000000000000000000000000000000"/>
    </joint>
    <joint name="HR_foot_joint_b" type="revolute">
        <parent link="HR_knee_link_b"/>
        <child link="HR_foot_link_b"/>
        <limit lower="0.0" upper="0.0" effort="-1" velocity="-1"/>

        <origin rpy="0.00000000000000000000000000000000 -0.00000000000000000000000000000000 0.00000000000000000000000000000000" xyz="0.01425000000745058059692382812500 0.00000000000000000000000000000000 0.00000000000000000000000000000000"/>
        <axis xyz="0.00000000000000000000000000000000 0.00000000000000000000000000000000 0.00000000000000000000000000000000"/>
    </joint>

    <gazebo>
        <joint name='FL_foot_joint' type='revolute'>
            <parent>FL_foot_link_a</parent>
            <child>FL_foot_link_b</child>
            <pose frame=''>0.0 0 0 0 0 0</pose>
            <axis>
                <xyz>0 0 1</xyz>
                <use_parent_model_frame>0</use_parent_model_frame>
                <limit>
                    <lower>-1.79769e+308</lower>
                    <upper>1.79769e+308</upper>
                    <effort>-1</effort>
                    <velocity>-1</velocity>
                </limit>
                <dynamics>
                    <spring_reference>0</spring_reference>
                    <spring_stiffness>0</spring_stiffness>
                    <damping>0</damping>
                </dynamics>
            </axis>
            <physics>
                <ode>
                    <limit>
                        <cfm>0</cfm>
                        <erp>0.2</erp>
                    </limit>
                    <suspension>
                        <cfm>0</cfm>
                        <erp>0.2</erp>
                    </suspension>
                </ode>
            </physics>
        </joint>

        <joint name='FR_foot_joint' type='revolute'>
            <parent>FR_foot_link_a</parent>
            <child>FR_foot_link_b</child>
            <pose frame=''>0.0 0 0 0 0 0</pose>
            <axis>
                <xyz>0 0 1</xyz>
                <use_parent_model_frame>0</use_parent_model_frame>
                <limit>
                    <lower>-1.79769e+308</lower>
                    <upper>1.79769e+308</upper>
                    <effort>-1</effort>
                    <velocity>-1</velocity>
                </limit>
                <dynamics>
                    <spring_reference>0</spring_reference>
                    <spring_stiffness>0</spring_stiffness>
                    <damping>0</damping>
                </dynamics>
            </axis>
            <physics>
                <ode>
                    <limit>
                        <cfm>0</cfm>
                        <erp>0.2</erp>
                    </limit>
                    <suspension>
                        <cfm>0</cfm>
                        <erp>0.2</erp>
                    </suspension>
                </ode>
            </physics>
        </joint>

        <joint name='HL_foot_joint' type='revolute'>
            <parent>HL_foot_link_a</parent>
            <child>HL_foot_link_b</child>
            <pose frame=''>0.0 0 0 0 0 0</pose>
            <axis>
                <xyz>0 0 1</xyz>
                <use_parent_model_frame>0</use_parent_model_frame>
                <limit>
                    <lower>-1.79769e+308</lower>
                    <upper>1.79769e+308</upper>
                    <effort>-1</effort>
                    <velocity>-1</velocity>
                </limit>
                <dynamics>
                    <spring_reference>0</spring_reference>
                    <spring_stiffness>0</spring_stiffness>
                    <damping>0</damping>
                </dynamics>
            </axis>
            <physics>
                <ode>
                    <limit>
                        <cfm>0</cfm>
                        <erp>0.2</erp>
                    </limit>
                    <suspension>
                        <cfm>0</cfm>
                        <erp>0.2</erp>
                    </suspension>
                </ode>
            </physics>
        </joint>

        <joint name='HR_foot_joint' type='revolute'>
            <parent>HR_foot_link_a</parent>
            <child>HR_foot_link_b</child>
            <pose frame=''>0 0 0 0 0 0</pose>
            <axis>
                <xyz>0 0 1</xyz>
                <use_parent_model_frame>0</use_parent_model_frame>
                <limit>
                    <lower>-1.79769e+308</lower>
                    <upper>1.79769e+308</upper>
                    <effort>-1</effort>
                    <velocity>-1</velocity>
                </limit>
                <dynamics>
                    <spring_reference>0</spring_reference>
                    <spring_stiffness>0</spring_stiffness>
                    <damping>0</damping>
                </dynamics>
            </axis>
            <physics>
                <ode>
                    <limit>
                        <cfm>0</cfm>
                        <erp>0.2</erp>
                    </limit>
                    <suspension>
                        <cfm>0</cfm>
                        <erp>0.2</erp>
                    </suspension>
                </ode>
            </physics>
        </joint>
    </gazebo>

    <transmission name="FL_hip_transmission_a">
        <type>transmission_interface/SimpleTransmission</type>
        <joint name="FL_hip_joint_a">
            <hardwareInterface>hardware_interface/EffortJointInterface</hardwareInterface>
        </joint>
        <actuator name="FL_hip_motor_a">
            <hardwareInterface>EffortJointInterface</hardwareInterface>
            <mechanicalReduction>1</mechanicalReduction>
        </actuator>
    </transmission>
    <transmission name="FR_hip_transmission_a">
        <type>transmission_interface/SimpleTransmission</type>
        <joint name="FR_hip_joint_a">
            <hardwareInterface>hardware_interface/EffortJointInterface</hardwareInterface>
        </joint>
        <actuator name="FR_hip_motor_a">
            <hardwareInterface>EffortJointInterface</hardwareInterface>
            <mechanicalReduction>1</mechanicalReduction>
        </actuator>
    </transmission>
    <transmission name="HL_hip_transmission_a">
        <type>transmission_interface/SimpleTransmission</type>
        <joint name="HL_hip_joint_a">
            <hardwareInterface>hardware_interface/EffortJointInterface</hardwareInterface>
        </joint>
        <actuator name="HL_hip_motor_a">
            <hardwareInterface>EffortJointInterface</hardwareInterface>
            <mechanicalReduction>1</mechanicalReduction>
        </actuator>
    </transmission>
    <transmission name="HR_hip_transmission_a">
        <type>transmission_interface/SimpleTransmission</type>
        <joint name="HR_hip_joint_a">
            <hardwareInterface>hardware_interface/EffortJointInterface</hardwareInterface>
        </joint>
        <actuator name="HR_hip_motor_a">
            <hardwareInterface>EffortJointInterface</hardwareInterface>
            <mechanicalReduction>1</mechanicalReduction>
        </actuator>
    </transmission>

    <transmission name="FL_hip_transmission_b">
        <type>transmission_interface/SimpleTransmission</type>
        <joint name="FL_hip_joint_b">
            <hardwareInterface>hardware_interface/EffortJointInterface</hardwareInterface>
        </joint>
        <actuator name="FL_hip_motor_b">
            <hardwareInterface>EffortJointInterface</hardwareInterface>
            <mechanicalReduction>1</mechanicalReduction>
        </actuator>
    </transmission>
    <transmission name="FR_hip_transmission_b">
        <type>transmission_interface/SimpleTransmission</type>
        <joint name="FR_hip_joint_b">
            <hardwareInterface>hardware_interface/EffortJointInterface</hardwareInterface>
        </joint>
        <actuator name="FR_hip_motor_b">
            <hardwareInterface>EffortJointInterface</hardwareInterface>
            <mechanicalReduction>1</mechanicalReduction>
        </actuator>
    </transmission>
    <transmission name="HL_hip_transmission_b">
        <type>transmission_interface/SimpleTransmission</type>
        <joint name="HL_hip_joint_b">
            <hardwareInterface>hardware_interface/EffortJointInterface</hardwareInterface>
        </joint>
        <actuator name="HL_hip_motor_b">
            <hardwareInterface>EffortJointInterface</hardwareInterface>
            <mechanicalReduction>1</mechanicalReduction>
        </actuator>
    </transmission>
    <transmission name="HR_hip_transmission_b">
        <type>transmission_interface/SimpleTransmission</type>
        <joint name="HR_hip_joint_b">
            <hardwareInterface>hardware_interface/EffortJointInterface</hardwareInterface>
        </joint>
        <actuator name="HR_hip_motor_b">
            <hardwareInterface>EffortJointInterface</hardwareInterface>
            <mechanicalReduction>1</mechanicalReduction>
        </actuator>
    </transmission>

    <gazebo>
          <plugin name="gazebo_ros_control" filename="libgazebo_ros_control.so">
            <robotNamespace>/phonebot</robotNamespace>
          </plugin>
    </gazebo>

</robot>
